Workbook

Sheet 구매목록
A1: Toccata v3.2 구매 목록 — 절감 선택 적용본
A2: 기준: 도면집 v10 절감안 탭 선택 코드(22개 부품 교체) · 가격은 2026-09-24~25 판매처 확인값(VAT·할인 반영, 원) · 구분: 기본 = 피아노에 들어가는 부품, 소모품 = 제작 중 쓰는 재료, 공구 = 제작용 공구
A3: 사용법: 파란 글씨(단위당 가격·수량·구매 O/X)만 고친다. 사지 않을 줄은 구매 칸을 X로 바꾸면 소계·최종 금액에서 빠진다(줄이 회색으로 바뀜). 예상 가격 = 단위당 가격 × 수량. 배송비는 판매처마다 따로 한 줄로 넣었다.
A5: No | B5: 부품명 | C5: 단위당 가격(원) | D5: 수량 | E5: 용도 | F5: 예상 가격(원) | G5: 구매 링크 | H5: 구분 | I5: 구매(O/X) | J5: 판매자 | K5: 부품 코드 | L5: 비고
A6: ■ 아이씨뱅큐
A7: 1 | B7: Raspberry Pi 5 2GB (라즈베리파이 5 2GB Raspberry pi 5) | C7: 119900 | D7: 1 | E7: FluidSynth 소프트웨어 신스를 돌리고 USB-MIDI 8개(O1~O7, PED) 입력을 한 곳에서 병합하는 중앙 컴퓨터. 소리는 USB 동글(L51)로 내보낸다(R25: HAT 없음, GPIO 배선 없음) | F7: =C7*D7 -> 119900 | G7: https://www.icbanq.com/P016286897 | H7: 기본 | I7: O | J7: 아이씨뱅큐 | K7: L01
A8: 2 | B8: TI DRV5055A2QLPG (TO-92-3 Linear Hall Effect Sensor, LCSC 경유) | C8: 891 | D8: 100 | E8: 건반마다 1개 + 예비 12. 표시면을 위로 눕혀 센서 바 포켓에 넣고 건반 밑 자석(Ø5×2)의 거리를 연속으로 잰다 | F8: =C8*D8 -> 89100 | G8: https://www.icbanq.com/P018076669 | H8: 기본 | I8: O | J8: 아이씨뱅큐 (LCSC 해외 재고) | K8: L20
A9: 3 | B9: XHHD 육각너트 M3 강철 (LCSC C133377) | C9: 11 | D9: 75 | E9: 출력 육각 포켓·통로에 앉히는 암나사. 레일 클램프 4 + 척추 세트스크루 4 = 모듈당 8개, 끝 부속 7, 스피커 브래킷 4 → 67개 + 예비 8 | F9: =C9*D9 -> 825 | G9: https://www.icbanq.com/P015976209 | H9: 기본 | I9: O | J9: 아이씨뱅큐 (LCSC 해외 재고) | K9: L31
A10: 4 | B10: Samsung CL31B104KCFNNNE (1206 100nF 100V X7R) | C10: 44 | D10: 100 | E10: 센서마다 1개(3V3–GND 디커플링, 센서 기판 아랫면) + PED 보드 | F10: =C10*D10 -> 4400 | G10: https://www.icbanq.com/P014968846 | H10: 기본 | I10: O | J10: 아이씨뱅큐 (LCSC 해외 재고) | K10: SE4 | L10: 삼성 CL31B104KCFNNNE(100 V). 판매처 사진이 안 열려 품번으로 확인
A11: 5 | B11: 핀헤더 소켓 1X40(2.54피치) | C11: 528 | D11: 1 | E11: 끝 부속 EXT 1×6 암 커넥터 2개(6+1핀 ×2)용 1줄. 4067 모듈은 암 헤더 없이 제어 기판에 직접 납땜(SE7) | F11: =C11*D11 -> 528 | G11: https://www.icbanq.com/P014161879 | H11: 기본 | I11: O | J11: 아이씨뱅큐 | K11: SE7
A12: 6 | B12: 핀헤더 1×40 - 2.54MM(S/T) _ 11.5MM(1단몰드) | C12: 165 | D12: 5 | E12: 4067 모듈 7개 × (16+8)핀 = 168핀 + EXT 수 커넥터 12핀 = 180핀 → 1×40 5줄(200핀) | F12: =C12*D12 -> 825 | G12: https://www.icbanq.com/P005666127 | H12: 기본 | I12: O | J12: 아이씨뱅큐 | K12: SE7 | L12: 모듈에 수 헤더가 들어 있으면 줄여도 된다
A13: 7 | B13: [BC256] Coms 스테레오 케이블 3M AUX 3극 Stereo 3.5 M/M 고급포장 | C13: 2860 | D13: 1 | E13: 댐퍼 페달 신호선. 한쪽 플러그를 잘라 페달 안 홀센서에 납땜(팁 = 출력, 링 = 3V3, 슬리브 = GND)하고, 다른 쪽은 CU의 PJ-313 잭(L15의 두 번째)에 꽂는다 | F13: =C13*D13 -> 2860 | G13: https://www.icbanq.com/P004711396 | H13: 기본 | I13: O | J13: 아이씨뱅큐 | K13: L50
A14: 8 | B14: XH-A232 (HW-404) TPA3110 2채널 앰프 보드 (제노 HAM6104) | C14: 2750 | D14: 1 | E14: 좌우 스피커(L07)를 울리는 D급 앰프. 20 V 버스(PD 트리거 L57 → 퓨즈 → 스위치)에서 8 Ω 채널당 약 21 W. 입력은 CU 트레이의 앰프 입력 잭(L15 ③)에서 받는다 | F14: =C14*D14 -> 2750 | G14: https://www.icbanq.com/P017179248 | H14: 기본 | I14: O | J14: 아이씨뱅큐 (제노) | K14: L53
A15: 9 | B15: Monolithic Capacitor 1uF X7R 50V (리드형 적층 세라믹) | C15: 133 | D15: 5 | E15: 앰프 입력의 저음 차단(고역 통과) 필터. 채널마다 1 µF 2개를 병렬(2 µF)로 직렬에 넣고 1 kΩ 풀다운(L29)과 묶어 약 80 Hz 아래를 6 dB/옥타브로 줄인다(D18) | F15: =C15*D15 -> 665 | G15: https://www.icbanq.com/P014159115 | H15: 기본 | I15: O | J15: 아이씨뱅큐 (동신전자) | K15: L56
A16: 10 | B16: 100W QC PD 트리거 디코이 고정출력 모듈 5V-20V (HAM6113, HUSB238) | C16: 4950 | D16: 1 | E16: 피아노의 전원 입력(USB-C). 벽 충전기(L62)나 보조배터리와 PD로 협상해 20 V를 받아 퓨즈(L60) → 스위치(L59) → 20 V 버스로 보낸다. I/O 판 안쪽 포켓에 끼워 USB-C 구멍이 밖을 향한다(R28) | F16: =C16*D16 -> 4950 | G16: https://www.icbanq.com/P017179277 | H16: 기본 | I16: O | J16: 아이씨뱅큐 (제노) | K16: L57
A17: 11 | B17: 200W XL4016 DC-DC 강압 컨버터 모듈 IN 4-40V OUT 1.25-36V 5A (HAM6415, XH-M401) | C17: 5170 | D17: 1 | E17: 20 V 버스 → 5.1 V. Pi 5(USB-C 전원선 C24)와 USB 허브(L17, DC 잭)에 전원을 준다. Pi에는 이 5 V만 들어간다(D16). CU 트레이 보스에 M3×10(L34) 4개로 고정(R28) | F17: =C17*D17 -> 5170 | G17: https://www.icbanq.com/P017179502 | H17: 기본 | I17: O | J17: 아이씨뱅큐 (제노) | K17: L58
A18: 12 | B18: 순간접착제 (814-2010) — V-tech 강력 순간접착제 5g (VT-041) | C18: 1100 | D18: 1 | E18: 센서 자석 Ø5×2(L21)·뚜껑 자석 Ø8×3(L65)을 포켓에 압입한 뒤 한 방울(리프 근처 사용 금지) | F18: =C18*D18 -> 1100 | G18: https://www.icbanq.com/P015309984 | H18: 소모품 | I18: O | J18: 아이씨뱅큐 (크레텍) | K18: ME8 | L18: 록타이트 401 20 g 대신(ME8). 성분·점도 표기는 페이지에 없다
A19: 13 | B19: 배송비 — 아이씨뱅큐 | C19: =IF(SUMIFS(F7:F18,I7:I18,"O")/1.1<50000,2700,0) -> 0 | D19: 1 | E19: 배송비 | F19: =C19*D19 -> 0 | H19: 기본 | I19: O | L19: 자동 계산: 공급가(VAT 제외) 5만원 미만이면 2,700원, 이상이면 무료
B20: 아이씨뱅큐 소계 | F20: =SUMIFS(F7:F19,I7:I19,"O") -> 233073
A22: ■ 엘레파츠
A23: 14 | B23: [화성고무] 피스고무발 / 28x5 (RUB-E2) | C23: 583 | D23: 20 | E23: 스피커 파트 2개(각 4개)와 가운데 유닛(6개)의 고무발 14개. 출력 받침 4 mm와 함께 뒷바를 22 mm 띄워 아래 앞쪽을 케이블 통로로 만든다(R27). 본체와 스피커 진동을 떼어 놓는다(D15) | F23: =C23*D23 -> 11660 | G23: https://www.eleparts.co.kr/goods/view?no=16628292 | H23: 기본 | I23: O | J23: 엘레파츠 | K23: L14
A24: 15 | B24: [BSUN] PJ-313 3.5Ф 스테레오잭 (이어폰잭) | C24: 198 | D24: 3 | E24: ① 왼쪽 볼 앞면 헤드폰 잭: 동글(L51) 출력이 팁·링으로 들어오고 팁·링 노멀 접점이 앰프 쪽으로 나간다. 헤드폰을 꽂으면 노멀 접점이 떨어져 스피커가 기계적으로 끊긴다(R15) ② I/O 판의 댐퍼 페달 잭(R24) ③ CU 트레이의 앰프 입력 잭: 선 ②의 플러그를 받아 저음 차단 RC를 거쳐 앰프(L53) 입력으로 보낸다(R26, 파트 분리) | F24: =C24*D24 -> 594 | G24: https://www.eleparts.co.kr/goods/view?no=67811 | H24: 기본 | I24: O | J24: 엘레파츠 | K24: L15
A25: 16 | B25: [ABCO] CFR 1/4W 5% 탄소피막 저항 1kΩ (10개 단위) | C25: 25 | D25: 10 | E25: 앰프 입력 풀다운 겸 저음 차단 필터(1 kΩ ×2), 필요하면 입력 감쇠(직렬 1 kΩ ×2), 페달 입력 직렬 1 kΩ | F25: =C25*D25 -> 250 | G25: https://www.eleparts.co.kr/goods/view?no=10911 | H25: 기본 | I25: O | J25: 엘레파츠 | K25: L29 | L25: 10개 단위 판매(M.O.Q 10)
A26: 17 | B26: [ABCO] CFR 1/4W 5% 탄소피막 저항 10kΩ (10개 단위) | C26: 25 | D26: 10 | E26: 예비(R25로 헤드폰 감지 회로가 빠져 설계상 필수는 아니다) | F26: =C26*D26 -> 250 | G26: https://www.eleparts.co.kr/goods/view?no=10951 | H26: 기본 | I26: O | J26: 엘레파츠 | K26: L29 | L26: 10개 단위 판매(M.O.Q 10)
A27: 18 | B27: [ABCO] CFR 1/4W 5% 탄소피막 저항 100kΩ (10개 단위) | C27: 25 | D27: 10 | E27: 페달 입력 풀다운 100 kΩ | F27: =C27*D27 -> 250 | G27: https://www.eleparts.co.kr/goods/view?no=10993 | H27: 기본 | I27: O | J27: 엘레파츠 | K27: L29 | L27: 10개 단위 판매(M.O.Q 10)
A28: 19 | B28: [ABCO] CFR 1/4W 5% 탄소피막 저항 100Ω (10개 단위) | C28: 25 | D28: 10 | E28: 예비·시험용 | F28: =C28*D28 -> 250 | G28: https://www.eleparts.co.kr/goods/view?no=10873 | H28: 기본 | I28: O | J28: 엘레파츠 | K28: L29 | L28: 10개 단위 판매(M.O.Q 10)
A29: 20 | B29: [Coms] IH190 USB-C(F) → USB-A(M) 변환 젠더 좌향 꺾임 | C29: 1700 | D29: 1 | E29: Apple 동글(USB-C 수)을 Pi 5 USB-A 포트에 꽂는 젠더 | F29: =C29*D29 -> 1700 | G29: https://www.eleparts.co.kr/goods/view?no=11043038 | H29: 기본 | I29: O | J29: 엘레파츠 | K29: L52
A30: 21 | B30: [ZX Electronics] KCD1-101A BLACK I/O 로커 스위치 (2P ON-OFF, 6A 250VAC / 10A 125VAC) | C30: 385 | D30: 1 | E30: 피아노 전원 스위치. PD 트리거·퓨즈 뒤 20 V 쪽에 넣어 앰프와 강압 모듈을 함께 켜고 끈다. I/O 판의 출력 구멍에 끼운다(스냅인, R28) | F30: =C30*D30 -> 385 | G30: https://www.eleparts.co.kr/goods/view?no=32569 | H30: 기본 | I30: O | J30: 엘레파츠 | K30: L59
A31: 22 | B31: [Coms] BU914 원형 휴즈 홀더 (5×20 mm, 인라인) | C31: 1110 | D31: 1 | E31: 20 V 버스 보호 퓨즈 홀더. PD 트리거 출력 + 선에 끼워 배선 단락 때 선이 타지 않게 한다 | F31: =C31*D31 -> 1110 | G31: https://www.eleparts.co.kr/goods/view?no=3237821 | H31: 기본 | I31: O | J31: 엘레파츠 | K31: L60
A32: 23 | B32: [LITTELFUSE] 0218005.MXP 5 A 지연형 퓨즈 5×20 mm | C32: 110 | D32: 5 | E32: 홀더에 넣는 5 A 지연형 퓨즈 1개 + 예비 4개(R28) | F32: =C32*D32 -> 550 | G32: https://www.eleparts.co.kr/goods/view?no=12766820 | H32: 기본 | I32: O | J32: 엘레파츠 | K32: L60 | L32: 최소 5개
A33: 24 | B33: [AMASS] XT30U-M 수 커넥터 18AWG 10cm 실리콘 와이어 | C33: 1760 | D33: 2 | E33: 앰프 쪽 스피커선 커넥터(좌우 2개). 통로 양 끝으로 나온 선에 납땜 | F33: =C33*D33 -> 3520 | G33: https://www.eleparts.co.kr/goods/view?no=12779720 | H33: 기본 | I33: O | J33: 엘레파츠 | K33: L61
A34: 25 | B34: [AMASS] XT30U-F 암 커넥터 18AWG 10cm 실리콘 와이어 | C34: 1760 | D34: 2 | E34: 스피커 쪽 커넥터(좌우 2개). 스피커 파트 앞판 아래로 나온 선에 납땜 | F34: =C34*D34 -> 3520 | G34: https://www.eleparts.co.kr/goods/view?no=12779721 | H34: 기본 | I34: O | J34: 엘레파츠 | K34: L61
A35: 26 | B35: [NA993] Coms USB 3.1 Type C 케이블 1M USB 2.0 A to C타입 White | C35: 1620 | D35: 8 | E35: 모듈 7개 + PED 보드 → 허브 USB 8가닥. 허브에 꽂힌 채 뒷바 아래 케이블 통로에 두고, 설치 때 모듈 쪽만 꽂는다(R27). 몰드 ≤12.5×7.5×25라 통로(높이 22)에 들어간다 | F35: =C35*D35 -> 12960 | G35: https://www.eleparts.co.kr/goods/view?no=4313490 | H35: 소모품 | I35: O | J35: 엘레파츠 | K35: C04
A36: 27 | B36: [EUNSUNG] Flat Data Cable 2651-16P (1m단위) | C36: 1529 | D36: 2 | E36: 센서 기판 → 제어 기판 리본(OUT 12 + 3V3 + GND, 약 180mm ×7), O1·O7 EXT 6심 연장선, 끝 부속 선 | F36: =C36*D36 -> 3058 | G36: https://www.eleparts.co.kr/goods/view?no=425 | H36: 소모품 | I36: O | J36: 엘레파츠 | K36: C05
A37: 28 | B37: [EUNSUNG] Flat Data Cable 2651-16P (1m단위) | C37: 1529 | D37: 1 | E37: 점퍼 단선 대신 리본 가닥으로: 센서 기판 3V3·GND 버스, 제어 기판 링크(SIG·S0~S3·EN), ID 브리지, 기판 배선(듀폰 점퍼 X1 대체) | F37: =C37*D37 -> 1529 | G37: https://www.eleparts.co.kr/goods/view?no=425 | H37: 소모품 | I37: O | J37: 엘레파츠 | K37: SE12 | L37: C05와 같은 품목을 1 m 더 산다. 주문 때 C05와 합쳐 3 m로 담아도 된다
A38: 29 | B38: [엘레파츠] 열수축튜브 530세트 - 프라스틱케이스 | C38: 6600 | D38: 1 | E38: EXT 헤더 커넥터, 선 이음, 페달 잭 뒤쪽 절연 | F38: =C38*D38 -> 6600 | G38: https://www.eleparts.co.kr/goods/view?no=8170311 | H38: 소모품 | I38: O | J38: 엘레파츠 | K38: C10
A39: 30 | B39: [KzPton] 캡톤테이프 10mm폭x33m | C39: 4059 | D39: 1 | E39: RP2040-Zero 아래 절연(캡톤 1장), 기판 아랫면 절연 | F39: =C39*D39 -> 4059 | G39: https://www.eleparts.co.kr/goods/view?no=557 | H39: 소모품 | I39: O | J39: 엘레파츠 | K39: C11
A40: 31 | B40: 티테크놀로지 케이블타이, 100개 [소/100mm] [블랙] [T-C2510B] | C40: 438 | D40: 1 | E40: USB 케이블을 뒷벽 고리에 묶어 당김 방지, EXT 커넥터 고정 · 케이블 통로 안 USB 8가닥 묶음(R27) | F40: =C40*D40 -> 438 | G40: https://www.eleparts.co.kr/goods/view?no=9100003 | H40: 소모품 | I40: O | J40: 엘레파츠 | K40: C12
A41: 32 | B41: [케이블스토어] 프리즘 국산 스피커케이블 50C 16AWG, 7M [블랙/PRS-50B07] | C41: 14300 | D41: 1 | E41: 앰프(L53) → 통로 → XT30 수(L61) 2쌍(좌우 각 약 0.6 m) + 스피커 파트 안 유닛 → XT30 암(각 약 0.3 m) + 20 V 전원선(PD 트리거 → 퓨즈 → 스위치 → 앰프·강압 모듈, 약 1 m) | F41: =C41*D41 -> 14300 | G41: https://www.eleparts.co.kr/goods/view?no=18388615 | H41: 소모품 | I41: O | J41: 엘레파츠 | K41: C13
A42: 33 | B42: [AV0176] Coms 스테레오 케이블 1.5M AUX 3극 Stereo 3.5 M/M | C42: 1710 | D42: 2 | E42: ① 동글(L51) → 왼쪽 볼 헤드폰 잭(L15 ①) ② 헤드폰 잭 노멀 접점 → CU 트레이 앰프 입력 잭(L15 ③). 두 선 모두 CU 쪽 플러그를 남기고 끝 부속 쪽을 잘라 잭에 납땜한다(선이 끝 부속에 붙어 다니고 CU에서 뽑는다, R26) | F42: =C42*D42 -> 3420 | G42: https://www.eleparts.co.kr/goods/view?no=2925673 | H42: 소모품 | I42: O | J42: 엘레파츠 | K42: C14
...

Sheet 판매처 요약
A1: No | B1: 구매 사이트 | C1: 품목 수(O) | D1: 소계(원) | E1: 비중
A2: 1 | B2: 아이씨뱅큐 | C2: =COUNTIFS(구매목록!I7:I19,"O",구매목록!E7:E19,"<>배송비") -> 12 | D2: =구매목록!F20 -> 233073 | E2: =IF(구매목록!F165=0,0,D2/구매목록!F165) -> 0.29013285
A3: 2 | B3: 엘레파츠 | C3: =COUNTIFS(구매목록!I23:I52,"O",구매목록!E23:E52,"<>배송비") -> 29 | D3: =구매목록!F53 -> 110093 | E3: =IF(구매목록!F165=0,0,D3/구매목록!F165) -> 0.13704546
A4: 3 | B4: 11번가 | C4: =COUNTIFS(구매목록!I56:I78,"O",구매목록!E56:E78,"<>배송비") -> 18 | D4: =구매목록!F79 -> 74150 | E4: =IF(구매목록!F165=0,0,D4/구매목록!F165) -> 0.092303058
A5: 4 | B5: 메카솔루션 | C5: =COUNTIFS(구매목록!I82:I85,"O",구매목록!E82:E85,"<>배송비") -> 3 | D5: =구매목록!F86 -> 12960 | E5: =IF(구매목록!F165=0,0,D5/구매목록!F165) -> 0.016132807
A6: 5 | B6: 파츠파츠 직영몰 | C6: =COUNTIFS(구매목록!I89:I91,"O",구매목록!E89:E91,"<>배송비") -> 2 | D6: =구매목록!F92 -> 32900 | E6: =IF(구매목록!F165=0,0,D6/구매목록!F165) -> 0.040954425
A7: 6 | B7: Bambu Lab KR 공식 스토어 | C7: =COUNTIFS(구매목록!I95:I99,"O",구매목록!E95:E99,"<>배송비") -> 4 | D7: =구매목록!F100 -> 93500 | E7: =IF(구매목록!F165=0,0,D7/구매목록!F165) -> 0.11639023
A8: 7 | B8: 다나와 (최저가 판매처) | C8: =COUNTIFS(구매목록!I103:I106,"O",구매목록!E103:E106,"<>배송비") -> 3 | D8: =구매목록!F107 -> 68990 | E8: =IF(구매목록!F165=0,0,D8/구매목록!F165) -> 0.085879811
A9: 8 | B9: 동진나무공장 | C9: =COUNTIFS(구매목록!I110:I111,"O",구매목록!E110:E111,"<>배송비") -> 2 | D9: =구매목록!F112 -> 40200 | E9: =IF(구매목록!F165=0,0,D9/구매목록!F165) -> 0.050041577
A10: 9 | B10: 대건상사 | C10: =COUNTIFS(구매목록!I115:I117,"O",구매목록!E115:E117,"<>배송비") -> 2 | D10: =구매목록!F118 -> 12740 | E10: =IF(구매목록!F165=0,0,D10/구매목록!F165) -> 0.015858947
A11: 10 | B11: 알씨뱅크 | C11: =COUNTIFS(구매목록!I121:I122,"O",구매목록!E121:E122,"<>배송비") -> 1 | D11: =구매목록!F123 -> 9500 | E11: =IF(구매목록!F165=0,0,D11/구매목록!F165) -> 0.011825746
A12: 11 | B12: 철물박사 | C12: =COUNTIFS(구매목록!I126:I127,"O",구매목록!E126:E127,"<>배송비") -> 1 | D12: =구매목록!F128 -> 7800 | E12: =IF(구매목록!F165=0,0,D12/구매목록!F165) -> 0.0097095597
A13: 12 | B13: 스튜디오분트 | C13: =COUNTIFS(구매목록!I131:I132,"O",구매목록!E131:E132,"<>배송비") -> 1 | D13: =구매목록!F133 -> 8500 | E13: =IF(구매목록!F165=0,0,D13/구매목록!F165) -> 0.01058093
A14: 13 | B14: 피아노모아 | C14: =COUNTIFS(구매목록!I136:I137,"O",구매목록!E136:E137,"<>배송비") -> 1 | D14: =구매목록!F138 -> 11500 | E14: =IF(구매목록!F165=0,0,D14/구매목록!F165) -> 0.014315376
A15: 14 | B15: Apple Store 온라인 | C15: =COUNTIFS(구매목록!I141,"O",구매목록!E141,"<>배송비") -> 1 | D15: =구매목록!F142 -> 14900 | E15: =IF(구매목록!F165=0,0,D15/구매목록!F165) -> 0.018547749
A16: 15 | B16: AliExpress | C16: =COUNTIFS(구매목록!I145:I146,"O",구매목록!E145:E146,"<>배송비") -> 2 | D16: =구매목록!F147 -> 13716 | E16: =IF(구매목록!F165=0,0,D16/구매목록!F165) -> 0.017073887
A17: 16 | B17: PINE STORE (Pine64 공식) | C17: =COUNTIFS(구매목록!I150:I153,"O",구매목록!E150:E153,"<>배송비") -> 3 | D17: =구매목록!F154 -> 58810 | E17: =IF(구매목록!F165=0,0,D17/구매목록!F165) -> 0.07320759
A18: 17 | B18: 무료 (다운로드) | C18: =COUNTIFS(구매목록!I157:I158,"O",구매목록!E157:E158,"<>배송비") -> 2 | D18: =구매목록!F159 -> 0 | E18: =IF(구매목록!F165=0,0,D18/구매목록!F165) -> 0
B19: 최종 금액 | C19: =SUM(C2:C18) -> 87 | D19: =SUM(D2:D18) -> 803332 | E19: =SUM(E2:E18) -> 1
